Workbook

Sheet 개발 일정표
B2: 팀 프로젝트 개발 일정표
B4: 전체 작업 | C4: 완료된 작업 | D4: 진행률 | F4: 송태현 | G4: 조종현 | H4: 구영주 | I4: 김현서
B5: =COUNTA(C7:C80) -> 74 | C5: =COUNTIF(I7:I80,"완료") -> 70 | D5: =IF(B5=0,0,C5/B5) -> 0.94594595
B6: 분류 | C6: 항목 | D6: 기능 | E6: 상세기능 | F6: 시작일 | G6: 종료일 | H6: 담당자 | I6: 상태 | J6: 비고 | K6: 6/29 | L6: 6/30 | M6: 7/1 | N6: 7/2 | O6: 7/3 | P6: 7/4 | Q6: 7/5 | R6: 7/6 | S6: 7/7 | T6: 7/8 | U6: 7/9 | V6: 7/10 | W6: 7/11 | X6: 7/12 | Y6: 7/13 | Z6: 7/14 | AA6: 7/15 | AB6: 7/16 | AC6: 7/17 | AD6: 7/18 | AE6: 7/19 | AF6: 7/20 | AG6: 7/21 | AH6: 7/22 | AI6: 7/23 | AJ6: 7/24 | AK6: 7/25 | AL6: 7/26 | AM6: 7/27 | AN6: 7/28 | AO6: 7/29 | AP6: 7/30 | AQ6: 7/31 | AR6: 8/1 | AS6: 8/2 | AT6: 8/3 | AU6: 8/4 | AV6: 8/5
B7: 공통/인프라 | C7: 프로젝트 초기 구성 | D7: 리포지토리 및 기본 골격 | E7: Spring Boot(MyBatis) + React(Vite) 초기 프로젝트 구성 | F7: 46202 | G7: 46204 | H7: 조종현 | I7: 완료
B8: 계정 관리 | C8: 회원가입/로그인 | D8: 로그인 화면 및 인증 | E8: 로그인 폼 제작 및 로그인 API 연동 | F8: 46204 | G8: 46205 | H8: 조종현 | I8: 완료
B9: 기획/QA | C9: 요구사항 정의 | D9: 요구사항 정리표 작성 | E9: 기능 요구사항 목록·중요도·권한 정리 | F9: 46204 | G9: 46209 | H9: 송태현 | I9: 완료 | J9: 커밋 이력 없음(문서 산출물)
B10: 계정 관리 | C10: 회원가입/로그인 | D10: access토큰 | E10: JWT 토큰 발급·저장·검증(JwtUtill) | F10: 46205 | G10: 46206 | H10: 조종현 | I10: 완료
B11: 공통/인프라 | C11: 라우팅 | D11: 역할 경로 분리 | E11: /fitb(B2B)·/fitc(B2C) 라우터 및 레이아웃 분리 | F11: 46205 | G11: 46206 | H11: 조종현 | I11: 완료
B12: 물품관리 | C12: 입력 폼 제작 | D12: 물품 데이터 입력 기능 | E12: 사장님이 물품의 정보를 기입할 수 있는 폼 제공 | F12: 46205 | G12: 46206 | H12: 송태현 | I12: 완료
B13: 물품관리 | C13: 물품관리 리스트 | D13: 물품관리 탭 요청 시 페이지 | E13: 메인 페이지에서 물품관리 버튼 클릭 시 제공하는 리스트 페이지 | F13: 46205 | G13: 46206 | H13: 송태현 | I13: 완료
B14: 물품관리 | C14: 물품관리 CRUD | D14: 입력·조회·수정·삭제 기능 | E14: h_item 테이블 CRUD 기능 및 디테일 정렬 | F14: 46206 | G14: 46209 | H14: 송태현 | I14: 완료
B15: B2C메뉴 | C15: 마이페이지 | D15: B2C·B2B 건의사항 | E15: 마이페이지 내 건의사항탭(전송, 내역, 처리상태) | F15: 46206 | G15: 46216 | H15: 조종현 | I15: 완료
B16: 계약 관리 | C16: 계약 도메인 구축 | D16: 계약서 리스트·작성·상세 화면 | E16: 계약서 리스트/작성 폼/상세 뷰어 구현, 유형별 조건부 입력 필드 | F16: 46206 | G16: 46209 | H16: 구영주 | I16: 완료 | J16: Contractpage·ContractNew·ContractDetail
B17: 정산관리 | C17: 정산 관리 리스트 | D17: 사장님 지출 입력 기능 | E17: 각 사장님이 사용한 지출내역 입력폼(h_expense) | F17: 46209 | G17: 46210 | H17: 송태현 | I17: 완료
B18: 회원 관리 | C18: 모델 입력 데이터 | D18: h_model_data 생성 | E18: 나이·방문횟수·운동시간·혼잡도 등 예측 피처 적재 | F18: 46209 | G18: 46211 | H18: 김현서 | I18: 완료
B19: 프로모션 | C19: 이탈율 예측 모델 | D19: 이탈율·이탈이유(불만이유) 예측 모델 생성 | E19: 이탈율이 얼마인지, 가장 큰 영향을 미치는 요소가 무엇인지 도출 | F19: 46209 | G19: 46216 | H19: 김현서 | I19: 완료
B20: 회원 관리 | C20: 설문 | D20: 회원 설문(NPS) 수집 | E20: h_survey 항목별 점수 및 부상 정보 수집 | F20: 46209 | G20: 46216 | H20: 김현서 | I20: 완료
B21: 프로모션 | C21: 이탈 예측 서빙 | D21: FastAPI·Streamlit 연동 | E21: healthModel 서비스화 및 Supabase 직접 조회 | F21: 46209 | G21: 46217 | H21: 김현서 | I21: 완료
B22: B2C메뉴 | C22: 마이페이지 | D22: 멤버십 조회 | E22: 보유 회원권 종류·이용 기간·잔여일 확인 | F22: 46209 | G22: 46218 | H22: 조종현 | I22: 완료
B23: 프로모션 | C23: 예측 결과 적재 | D23: h_churn_result 저장 | E23: 이탈확률·top1~3 이탈요인을 일자별 이력으로 누적 | F23: 46209 | G23: 46226 | H23: 김현서 | I23: 완료
B24: 회원 관리 | C24: 자동 회원가입 | D24: 미가입 수신자 자동가입 | E24: 계약 서명 시 autoJoin 호출(서명 트랜잭션 내 처리) | F24: 46210 | G24: 46210 | H24: 조종현 | I24: 완료
B25: 출석관리 | C25: 출석 체크 | D25: 체크인 기록 저장 | E25: 헬스장 방문 시 h_check_inout 기록(이탈 예측 기초 데이터) | F25: 46210 | G25: 46212 | H25: 조종현 | I25: 완료
B26: 정산관리 | C26: 커미션 | D26: 관계사 커미션 집계 | E26: 월별 커미션 생성·조회(h_settlement) | F26: 46210 | G26: 46216 | H26: 송태현 | I26: 완료
B27: 계약 관리 | C27: 계약 도메인 구축 | D27: 데이터 모델 정비 | E27: 생년월일·하루 평균 운동시간(시/분 분리) 필드 추가, 날짜 타입 String→LocalDate 전환, 패키지 user→contract 정리 | F27: 46210 | G27: 46210 | H27: 구영주 | I27: 완료 | J27: 백엔드 4계층(Controller/Service/Mapper/XML)
B28: 물품관리 | C28: 리스트 부가기능 | D28: 페이징·정렬·CSV 내보내기 | E28: 페이저 클래스 적용, 정렬 옵션, 물품 리스트 CSV export | F28: 46211 | G28: 46211 | H28: 송태현 | I28: 완료
B29: 공통/인프라 | C29: 알림 | D29: 알림 라인·헤더 알림 | E29: h_alarm 목록 조회 및 읽음 처리 | F29: 46211 | G29: 46216 | H29: 조종현 | I29: 완료
B30: 계약 관리 | C30: 계약 도메인 구축 | D30: 미가입 수신자 자동가입 | E30: 서명 완료 시 자동 회원가입 호출, 서명-가입 단일 트랜잭션(실패 시 함께 롤백) | F30: 46211 | G30: 46211 | H30: 구영주 | I30: 완료 | J30: @Transactional 체인
B31: 대시보드 | C31: 도메인 구축 | D31: 위젯 시스템 신설 | E31: 대시보드 4계층 신설, 테넌트 격리(role 정규화), 위젯 활성화 정책(데이터 有 기본 켜짐·소실 시 잠금), 차트 쿼리 안정화 | F31: 46211 | G31: 46211 | H31: 구영주 | I31: 완료 | J31: 사용자별 위젯 설정 저장
B32: 쿠폰/프로모션 | C32: 쿠폰 관리 | D32: 쿠폰 종류 등록·발급 | E32: h_coupon_type 정의 및 h_coupon 발급, 중복 발급 방지 | F32: 46212 | G32: 46223 | H32: 조종현 | I32: 완료
B33: 프로모션 | C33: 이탈 분석 화면 | D33: B2B 이탈 분석 리스트 | E33: 이탈 위험 회원 리스트·상세(B2B 마이페이지) | F33: 46212 | G33: 46225 | H33: 김현서 | I33: 완료
B34: 공통/인프라 | C34: 알림 | D34: 도메인 이벤트 알림 발송 | E34: 물품·정산·결제 이벤트 알림 발송 연동 | F34: 46212 | G34: 46226 | H34: 송태현 | I34: 완료
B35: 계약 관리 | C35: 계약 도메인 구축 | D35: 검증용 시드 데이터 구축 | E35: 발행 API로 계약 75건 적재, 상태·날짜 정합화, 출석 358건·설문 49건 생성, 정합성 검증 쿼리 4종 | F35: 46212 | G35: 46212 | H35: 구영주 | I35: 완료 | J35: 대시보드·이탈모델 검증용
B36: 대시보드 | C36: 도메인 구축 | D36: 집계·라우트 보강 | E36: Service·Mapper 집계 로직 보강, 대시보드 라우트 추가, 시드 데이터로 위젯 검증 | F36: 46212 | G36: 46212 | H36: 구영주 | I36: 완료
B37: 결제 관리 | C37: 결제 페이지 | D37: 계약 결제 처리 | E37: 계약 서명 후 결제(h_pay/h_payment), 할부·쿠폰 적용 | F37: 46213 | G37: 46217 | H37: 송태현 | I37: 완료
B38: 계약 관리 | C38: 계약 도메인 구축 | D38: 발행→서명→결제 동선 | E38: 회원 계약서 발행·서명 흐름 보완, 결제 라우트 연결 | F38: 46213 | G38: 46217 | H38: 구영주 | I38: 완료
B39: 쿠폰/프로모션 | C39: 쿠폰 관리 | D39: 쿠폰 상태 스케줄링 | E39: 미사용/사용완료/유효기간만료 상태 자동 갱신 | F39: 46216 | G39: 46223 | H39: 조종현 | I39: 완료
B40: 정산관리 | C40: 매출 | D40: 결제 기반 매출 집계 | E40: 매출·지출·순이익 집계 및 정산 페이지 반영 | F40: 46216 | G40: 46225 | H40: 송태현 | I40: 완료
B41: AI 비서 | C41: Phase 0~1 구축 | D41: AI 도메인·오케스트레이터 | E41: AI 패키지 신설(오케스트레이터·도구 화이트리스트·role 게이팅·감사 로그), Anthropic API(Tool Use) 멀티턴 루프, SSE 스트리밍, ERD 3종, 프론트 챗 패널 | F41: 46216 | G41: 46216 | H41: 구영주 | I41: 완료 | J41: 21파일 +1,851줄
B42: 계정 관리 | C42: 회원가입/로그인 | D42: refresh토큰 | E42: 토큰 발급·저장·검증(h_refresh_token), 로그아웃 시 소거 | F42: 46217 | G42: 46217 | H42: 조종현 | I42: 완료
...

Sheet 담당자별 요약
B2: 담당자별 작업 요약
B4: 담당자 | C4: git 계정 | D4: 전체 | E4: 완료 | F4: 진행 중 | G4: 대기 | H4: 완료율
B5: 송태현 | C5: Taehyun-0502 | D5: =COUNTIF('개발 일정표'!$H$7:$H$80,$B5) -> 17 | E5: =COUNTIFS('개발 일정표'!$H$7:$H$80,$B5,'개발 일정표'!$I$7:$I$80,"완료") -> 16 | F5: =COUNTIFS('개발 일정표'!$H$7:$H$80,$B5,'개발 일정표'!$I$7:$I$80,"진행 중") -> 0 | G5: =COUNTIFS('개발 일정표'!$H$7:$H$80,$B5,'개발 일정표'!$I$7:$I$80,"대기") -> 1 | H5: =IF(D5=0,0,E5/D5) -> 0.94117647
B6: 조종현 | C6: Jonghyun / zxc159285-prog | D6: =COUNTIF('개발 일정표'!$H$7:$H$80,$B6) -> 14 | E6: =COUNTIFS('개발 일정표'!$H$7:$H$80,$B6,'개발 일정표'!$I$7:$I$80,"완료") -> 14 | F6: =COUNTIFS('개발 일정표'!$H$7:$H$80,$B6,'개발 일정표'!$I$7:$I$80,"진행 중") -> 0 | G6: =COUNTIFS('개발 일정표'!$H$7:$H$80,$B6,'개발 일정표'!$I$7:$I$80,"대기") -> 0 | H6: =IF(D6=0,0,E6/D6) -> 1
B7: 구영주 | C7: greyth93-ship-it | D7: =COUNTIF('개발 일정표'!$H$7:$H$80,$B7) -> 33 | E7: =COUNTIFS('개발 일정표'!$H$7:$H$80,$B7,'개발 일정표'!$I$7:$I$80,"완료") -> 30 | F7: =COUNTIFS('개발 일정표'!$H$7:$H$80,$B7,'개발 일정표'!$I$7:$I$80,"진행 중") -> 0 | G7: =COUNTIFS('개발 일정표'!$H$7:$H$80,$B7,'개발 일정표'!$I$7:$I$80,"대기") -> 3 | H7: =IF(D7=0,0,E7/D7) -> 0.90909091
B8: 김현서 | C8: hyunseo0504 (HS) | D8: =COUNTIF('개발 일정표'!$H$7:$H$80,$B8) -> 10 | E8: =COUNTIFS('개발 일정표'!$H$7:$H$80,$B8,'개발 일정표'!$I$7:$I$80,"완료") -> 10 | F8: =COUNTIFS('개발 일정표'!$H$7:$H$80,$B8,'개발 일정표'!$I$7:$I$80,"진행 중") -> 0 | G8: =COUNTIFS('개발 일정표'!$H$7:$H$80,$B8,'개발 일정표'!$I$7:$I$80,"대기") -> 0 | H8: =IF(D8=0,0,E8/D8) -> 1
B9: 합계 | D9: =SUM(D5:D8) -> 74 | E9: =SUM(E5:E8) -> 70 | F9: =SUM(F5:F8) -> 0 | G9: =SUM(G5:G8) -> 4 | H9: =IF(D9=0,0,E9/D9) -> 0.94594595
B11: ※ 일정·담당자는 health_Project git 커밋 이력(2026-06-29 ~ 2026-07-28) 기준으로 산출했습니다. '대기' 항목은 CLAUDE.md 구현 현황의 미구현 항목이며 종료일은 예상치입니다.
